Workbook

Sheet Concepts
A1: id | B1: name | C1: is_quantity | D1: is_ratio | E1: is_relationship | F1: groups | G1: broader | H1: parts | I1: related | J1: same_as | K1: other_properties | L1: notation_tex | M1: wikidata_id | N1: wikidata_url | O1: definition | P1: name_fr | Q1: definition_fr
A2: Acceleration | B2: Acceleration | C2: =countif(Quantities!A:A,A2) -> 0 | D2: =IFERROR(__xludf.DUMMYFUNCTION("REGEXMATCH(A2,""(?i)ratio"")"),TRUE) -> TRUE | E2: =IFERROR(__xludf.DUMMYFUNCTION("REGEXMATCH(A2,""(?i)relationship"")"),FALSE) -> FALSE
A3: Action | B3: Action | C3: =countif(Quantities!A:A,A3) -> 0 | D3: =IFERROR(__xludf.DUMMYFUNCTION("REGEXMATCH(A3,""(?i)ratio"")"),FALSE) -> FALSE | E3: =IFERROR(__xludf.DUMMYFUNCTION("REGEXMATCH(A3,""(?i)relationship"")"),FALSE) -> FALSE | N3: =if(isblank(M3),"",hyperlink("https://www.wikidata.org/wiki/"&M3,M3)) | O3: A physical quantity that describes the motion of a system.
A4: AlphaParticle | B4: Alpha Particle | C4: =countif(Quantities!A:A,A4) -> 0 | D4: =IFERROR(__xludf.DUMMYFUNCTION("REGEXMATCH(A4,""(?i)ratio"")"),FALSE) -> FALSE | E4: =IFERROR(__xludf.DUMMYFUNCTION("REGEXMATCH(A4,""(?i)relationship"")"),FALSE) -> FALSE | G4: Particle | M4: Q103517 | N4: =if(isblank(M4),"",hyperlink("https://www.wikidata.org/wiki/"&M4,M4)) -> Q103517
A5: AlphaParticleElectronMassRatio | B5: =VLOOKUP(A5,Quantities!A:B,2,false) -> Alpha Particle - Electron Mass Ratio | C5: =countif(Quantities!A:A,A5) -> 1 | D5: =IFERROR(__xludf.DUMMYFUNCTION("REGEXMATCH(A5,""(?i)ratio"")"),TRUE) -> TRUE | E5: =IFERROR(__xludf.DUMMYFUNCTION("REGEXMATCH(A5,""(?i)relationship"")"),FALSE) -> FALSE | H5: AlphaParticle,Electron,MassRatio | N5: =if(isblank(M5),"",hyperlink("https://www.wikidata.org/wiki/"&M5,M5))
A6: AlphaParticleMass | B6: =VLOOKUP(A6,Quantities!A:B,2,false) -> Alpha Particle Mass | C6: =countif(Quantities!A:A,A6) -> 1 | D6: =IFERROR(__xludf.DUMMYFUNCTION("REGEXMATCH(A6,""(?i)ratio"")"),FALSE) -> FALSE | E6: =IFERROR(__xludf.DUMMYFUNCTION("REGEXMATCH(A6,""(?i)relationship"")"),FALSE) -> FALSE | H6: AlphaParticle,Mass | N6: =if(isblank(M6),"",hyperlink("https://www.wikidata.org/wiki/"&M6,M6))
A7: AlphaParticleMassEnergyEquivalent | B7: =VLOOKUP(A7,Quantities!A:B,2,false) -> Alpha Particle Mass Energy Equivalent | C7: =countif(Quantities!A:A,A7) -> 1 | D7: =IFERROR(__xludf.DUMMYFUNCTION("REGEXMATCH(A7,""(?i)ratio"")"),FALSE) -> FALSE | E7: =IFERROR(__xludf.DUMMYFUNCTION("REGEXMATCH(A7,""(?i)relationship"")"),FALSE) -> FALSE | H7: AlphaParticleMass,EnergyEquivalent | N7: =if(isblank(M7),"",hyperlink("https://www.wikidata.org/wiki/"&M7,M7))
A8: AlphaParticleMolarMass | B8: =VLOOKUP(A8,Quantities!A:B,2,false) -> Alpha Particle Molar Mass | C8: =countif(Quantities!A:A,A8) -> 1 | D8: =IFERROR(__xludf.DUMMYFUNCTION("REGEXMATCH(A8,""(?i)ratio"")"),FALSE) -> FALSE | E8: =IFERROR(__xludf.DUMMYFUNCTION("REGEXMATCH(A8,""(?i)relationship"")"),FALSE) -> FALSE | H8: AlphaParticle,MolarMass | N8: =if(isblank(M8),"",hyperlink("https://www.wikidata.org/wiki/"&M8,M8))
A9: AlphaParticleProtonMassRatio | B9: =VLOOKUP(A9,Quantities!A:B,2,false) -> Alpha Particle - Proton Mass Ratio | C9: =countif(Quantities!A:A,A9) -> 1 | D9: =IFERROR(__xludf.DUMMYFUNCTION("REGEXMATCH(A9,""(?i)ratio"")"),TRUE) -> TRUE | E9: =IFERROR(__xludf.DUMMYFUNCTION("REGEXMATCH(A9,""(?i)relationship"")"),FALSE) -> FALSE | H9: AlphaParticle,Proton,MassRatio | N9: =if(isblank(M9),"",hyperlink("https://www.wikidata.org/wiki/"&M9,M9))
A10: AlphaParticleRelativeAtomicMass | B10: =VLOOKUP(A10,Quantities!A:B,2,false) -> Alpha Particle Relative Atomic Mass | C10: =countif(Quantities!A:A,A10) -> 1 | D10: =IFERROR(__xludf.DUMMYFUNCTION("REGEXMATCH(A10,""(?i)ratio"")"),FALSE) -> FALSE | E10: =IFERROR(__xludf.DUMMYFUNCTION("REGEXMATCH(A10,""(?i)relationship"")"),FALSE) -> FALSE | H10: AlphaParticle,RelativeAtomicMass | N10: =if(isblank(M10),"",hyperlink("https://www.wikidata.org/wiki/"&M10,M10))
A11: AlphaParticleRmsChargeRadius | B11: =VLOOKUP(A11,Quantities!A:B,2,false) -> Alpha Particle Rms Charge Radius | C11: =countif(Quantities!A:A,A11) -> 1 | D11: =IFERROR(__xludf.DUMMYFUNCTION("REGEXMATCH(A11,""(?i)ratio"")"),FALSE) -> FALSE | E11: =IFERROR(__xludf.DUMMYFUNCTION("REGEXMATCH(A11,""(?i)relationship"")"),FALSE) -> FALSE | H11: AlphaParticle,RmsChargeRadius | N11: =if(isblank(M11),"",hyperlink("https://www.wikidata.org/wiki/"&M11,M11))
A12: Ampere | B12: Ampere | C12: =countif(Quantities!A:A,A12) -> 0 | D12: =IFERROR(__xludf.DUMMYFUNCTION("REGEXMATCH(A12,""(?i)ratio"")"),FALSE) -> FALSE | E12: =IFERROR(__xludf.DUMMYFUNCTION("REGEXMATCH(A12,""(?i)relationship"")"),FALSE) -> FALSE
A13: AngstromStar | B13: =VLOOKUP(A13,Quantities!A:B,2,false) -> Angstrom Star | C13: =countif(Quantities!A:A,A13) -> 1 | D13: =IFERROR(__xludf.DUMMYFUNCTION("REGEXMATCH(A13,""(?i)ratio"")"),FALSE) -> FALSE | E13: =IFERROR(__xludf.DUMMYFUNCTION("REGEXMATCH(A13,""(?i)relationship"")"),FALSE) -> FALSE | N13: =if(isblank(M13),"",hyperlink("https://www.wikidata.org/wiki/"&M13,M13))
A14: AtomicMass | B14: Atomic Mass | C14: =countif(Quantities!A:A,A14) -> 0 | D14: =IFERROR(__xludf.DUMMYFUNCTION("REGEXMATCH(A14,""(?i)ratio"")"),FALSE) -> FALSE | E14: =IFERROR(__xludf.DUMMYFUNCTION("REGEXMATCH(A14,""(?i)relationship"")"),FALSE) -> FALSE | N14: =if(isblank(M14),"",hyperlink("https://www.wikidata.org/wiki/"&M14,M14))
A15: AtomicMassConstant | B15: =VLOOKUP(A15,Quantities!A:B,2,false) -> Atomic Mass Constant | C15: =countif(Quantities!A:A,A15) -> 1 | D15: =IFERROR(__xludf.DUMMYFUNCTION("REGEXMATCH(A15,""(?i)ratio"")"),FALSE) -> FALSE | E15: =IFERROR(__xludf.DUMMYFUNCTION("REGEXMATCH(A15,""(?i)relationship"")"),FALSE) -> FALSE | H15: AtomicMass | N15: =if(isblank(M15),"",hyperlink("https://www.wikidata.org/wiki/"&M15,M15))
A16: AtomicMassConstantEnergyEquivalent | B16: =VLOOKUP(A16,Quantities!A:B,2,false) -> Atomic Mass Constant Energy Equivalent | C16: =countif(Quantities!A:A,A16) -> 1 | D16: =IFERROR(__xludf.DUMMYFUNCTION("REGEXMATCH(A16,""(?i)ratio"")"),FALSE) -> FALSE | E16: =IFERROR(__xludf.DUMMYFUNCTION("REGEXMATCH(A16,""(?i)relationship"")"),FALSE) -> FALSE | H16: AtomicMassConstant,EnergyEquivalent | N16: =if(isblank(M16),"",hyperlink("https://www.wikidata.org/wiki/"&M16,M16))
A17: AtomicMassUnit | B17: AtomicMassUnit | C17: =countif(Quantities!A:A,A17) -> 0 | D17: =IFERROR(__xludf.DUMMYFUNCTION("REGEXMATCH(A17,""(?i)ratio"")"),FALSE) -> FALSE | E17: =IFERROR(__xludf.DUMMYFUNCTION("REGEXMATCH(A17,""(?i)relationship"")"),FALSE) -> FALSE
A18: AtomicMassUnitElectronVoltRelationship | B18: =VLOOKUP(A18,Quantities!A:B,2,false) -> Atomic Mass Unit - Electronvolt Relationship | C18: =countif(Quantities!A:A,A18) -> 1 | D18: =IFERROR(__xludf.DUMMYFUNCTION("REGEXMATCH(A18,""(?i)ratio"")"),FALSE) -> FALSE | E18: =IFERROR(__xludf.DUMMYFUNCTION("REGEXMATCH(A18,""(?i)relationship"")"),TRUE) -> TRUE | H18: AtomicMassUnit,ElectronVolt,Relationship | N18: =if(isblank(M18),"",hyperlink("https://www.wikidata.org/wiki/"&M18,M18))
A19: AtomicMassUnitHartreeRelationship | B19: =VLOOKUP(A19,Quantities!A:B,2,false) -> Atomic Mass Unit - Hartree Relationship | C19: =countif(Quantities!A:A,A19) -> 1 | D19: =IFERROR(__xludf.DUMMYFUNCTION("REGEXMATCH(A19,""(?i)ratio"")"),FALSE) -> FALSE | E19: =IFERROR(__xludf.DUMMYFUNCTION("REGEXMATCH(A19,""(?i)relationship"")"),TRUE) -> TRUE | H19: AtomicMassUnit,Hartree,Relationship | N19: =if(isblank(M19),"",hyperlink("https://www.wikidata.org/wiki/"&M19,M19))
A20: AtomicMassUnitHertzRelationship | B20: =VLOOKUP(A20,Quantities!A:B,2,false) -> Atomic Mass Unit - Hertz Relationship | C20: =countif(Quantities!A:A,A20) -> 1 | D20: =IFERROR(__xludf.DUMMYFUNCTION("REGEXMATCH(A20,""(?i)ratio"")"),FALSE) -> FALSE | E20: =IFERROR(__xludf.DUMMYFUNCTION("REGEXMATCH(A20,""(?i)relationship"")"),TRUE) -> TRUE | H20: AtomicMassUnit,Hertz,Relationship | N20: =if(isblank(M20),"",hyperlink("https://www.wikidata.org/wiki/"&M20,M20))
A21: AtomicMassUnitInverseMeterRelationship | B21: =VLOOKUP(A21,Quantities!A:B,2,false) -> Atomic Mass Unit - Inverse Meter Relationship | C21: =countif(Quantities!A:A,A21) -> 1 | D21: =IFERROR(__xludf.DUMMYFUNCTION("REGEXMATCH(A21,""(?i)ratio"")"),FALSE) -> FALSE | E21: =IFERROR(__xludf.DUMMYFUNCTION("REGEXMATCH(A21,""(?i)relationship"")"),TRUE) -> TRUE | H21: AtomicMassUnit,InverseMeter,Relationship | N21: =if(isblank(M21),"",hyperlink("https://www.wikidata.org/wiki/"&M21,M21))
A22: AtomicMassUnitJouleRelationship | B22: =VLOOKUP(A22,Quantities!A:B,2,false) -> Atomic Mass Unit - Joule Relationship | C22: =countif(Quantities!A:A,A22) -> 1 | D22: =IFERROR(__xludf.DUMMYFUNCTION("REGEXMATCH(A22,""(?i)ratio"")"),FALSE) -> FALSE | E22: =IFERROR(__xludf.DUMMYFUNCTION("REGEXMATCH(A22,""(?i)relationship"")"),TRUE) -> TRUE | H22: AtomicMassUnit,Joule,Relationship | N22: =if(isblank(M22),"",hyperlink("https://www.wikidata.org/wiki/"&M22,M22))
A23: AtomicMassUnitKelvinRelationship | B23: =VLOOKUP(A23,Quantities!A:B,2,false) -> Atomic Mass Unit - Kelvin Relationship | C23: =countif(Quantities!A:A,A23) -> 1 | D23: =IFERROR(__xludf.DUMMYFUNCTION("REGEXMATCH(A23,""(?i)ratio"")"),FALSE) -> FALSE | E23: =IFERROR(__xludf.DUMMYFUNCTION("REGEXMATCH(A23,""(?i)relationship"")"),TRUE) -> TRUE | H23: AtomicMassUnit,Kelvin,Relationship | N23: =if(isblank(M23),"",hyperlink("https://www.wikidata.org/wiki/"&M23,M23))
A24: AtomicMassUnitKilogramRelationship | B24: =VLOOKUP(A24,Quantities!A:B,2,false) -> Atomic Mass Unit - Kilogram Relationship | C24: =countif(Quantities!A:A,A24) -> 1 | D24: =IFERROR(__xludf.DUMMYFUNCTION("REGEXMATCH(A24,""(?i)ratio"")"),FALSE) -> FALSE | E24: =IFERROR(__xludf.DUMMYFUNCTION("REGEXMATCH(A24,""(?i)relationship"")"),TRUE) -> TRUE | H24: AtomicMassUnit,Kilogram,Relationship | N24: =if(isblank(M24),"",hyperlink("https://www.wikidata.org/wiki/"&M24,M24))
A25: AtomicUnit | B25: Atomic Unit | C25: =countif(Quantities!A:A,A25) -> 0 | D25: =IFERROR(__xludf.DUMMYFUNCTION("REGEXMATCH(A25,""(?i)ratio"")"),FALSE) -> FALSE | E25: =IFERROR(__xludf.DUMMYFUNCTION("REGEXMATCH(A25,""(?i)relationship"")"),FALSE) -> FALSE | N25: =if(isblank(M25),"",hyperlink("https://www.wikidata.org/wiki/"&M25,M25)) | O25: A set of fundamental units used in atomic and molecular physics and quantum chemistry.
A26: AtomicUnitOf1stHyperpolarizability | B26: =VLOOKUP(A26,Quantities!A:B,2,false) -> Atomic Unit Of First Hyperpolarizability | C26: =countif(Quantities!A:A,A26) -> 1 | D26: =IFERROR(__xludf.DUMMYFUNCTION("REGEXMATCH(A26,""(?i)ratio"")"),FALSE) -> FALSE | E26: =IFERROR(__xludf.DUMMYFUNCTION("REGEXMATCH(A26,""(?i)relationship"")"),FALSE) -> FALSE | H26: AtomicUnit,Hyperpolarizablity | N26: =if(isblank(M26),"",hyperlink("https://www.wikidata.org/wiki/"&M26,M26))
A27: AtomicUnitOf2ndHyperpolarizability | B27: =VLOOKUP(A27,Quantities!A:B,2,false) -> Atomic Unit Of Second Hyperpolarizability | C27: =countif(Quantities!A:A,A27) -> 1 | D27: =IFERROR(__xludf.DUMMYFUNCTION("REGEXMATCH(A27,""(?i)ratio"")"),FALSE) -> FALSE | E27: =IFERROR(__xludf.DUMMYFUNCTION("REGEXMATCH(A27,""(?i)relationship"")"),FALSE) -> FALSE | H27: AtomicUnit,Hyperpolarizablity | N27: =if(isblank(M27),"",hyperlink("https://www.wikidata.org/wiki/"&M27,M27))
A28: AtomicUnitOfAction | B28: =VLOOKUP(A28,Quantities!A:B,2,false) -> Atomic Unit Of Action | C28: =countif(Quantities!A:A,A28) -> 1 | D28: =IFERROR(__xludf.DUMMYFUNCTION("REGEXMATCH(A28,""(?i)ratio"")"),FALSE) -> FALSE | E28: =IFERROR(__xludf.DUMMYFUNCTION("REGEXMATCH(A28,""(?i)relationship"")"),FALSE) -> FALSE | H28: AtomicUnit,Action | N28: =if(isblank(M28),"",hyperlink("https://www.wikidata.org/wiki/"&M28,M28))
A29: AtomicUnitOfCharge | B29: =VLOOKUP(A29,Quantities!A:B,2,false) -> Atomic Unit Of Charge | C29: =countif(Quantities!A:A,A29) -> 1 | D29: =IFERROR(__xludf.DUMMYFUNCTION("REGEXMATCH(A29,""(?i)ratio"")"),FALSE) -> FALSE | E29: =IFERROR(__xludf.DUMMYFUNCTION("REGEXMATCH(A29,""(?i)relationship"")"),FALSE) -> FALSE | H29: AtomicUnit,Charge | N29: =if(isblank(M29),"",hyperlink("https://www.wikidata.org/wiki/"&M29,M29))
A30: AtomicUnitOfChargeDensity | B30: =VLOOKUP(A30,Quantities!A:B,2,false) -> Atomic Unit Of Charge Density | C30: =countif(Quantities!A:A,A30) -> 1 | D30: =IFERROR(__xludf.DUMMYFUNCTION("REGEXMATCH(A30,""(?i)ratio"")"),FALSE) -> FALSE | E30: =IFERROR(__xludf.DUMMYFUNCTION("REGEXMATCH(A30,""(?i)relationship"")"),FALSE) -> FALSE | H30: AtomicUnit,ChargeDensity | N30: =if(isblank(M30),"",hyperlink("https://www.wikidata.org/wiki/"&M30,M30))
A31: AtomicUnitOfCurrent | B31: =VLOOKUP(A31,Quantities!A:B,2,false) -> Atomic Unit Of Current | C31: =countif(Quantities!A:A,A31) -> 1 | D31: =IFERROR(__xludf.DUMMYFUNCTION("REGEXMATCH(A31,""(?i)ratio"")"),FALSE) -> FALSE | E31: =IFERROR(__xludf.DUMMYFUNCTION("REGEXMATCH(A31,""(?i)relationship"")"),FALSE) -> FALSE | H31: AtomicUnit,Current | N31: =if(isblank(M31),"",hyperlink("https://www.wikidata.org/wiki/"&M31,M31))
A32: AtomicUnitOfElectricDipoleMoment | B32: =VLOOKUP(A32,Quantities!A:B,2,false) -> Atomic Unit Of Electric Dipole Moment | C32: =countif(Quantities!A:A,A32) -> 1 | D32: =IFERROR(__xludf.DUMMYFUNCTION("REGEXMATCH(A32,""(?i)ratio"")"),FALSE) -> FALSE | E32: =IFERROR(__xludf.DUMMYFUNCTION("REGEXMATCH(A32,""(?i)relationship"")"),FALSE) -> FALSE | H32: AtomicUnit,ElectricDipoleMoment | N32: =if(isblank(M32),"",hyperlink("https://www.wikidata.org/wiki/"&M32,M32))
A33: AtomicUnitOfElectricField | B33: =VLOOKUP(A33,Quantities!A:B,2,false) -> Atomic Unit Of Electric Field | C33: =countif(Quantities!A:A,A33) -> 1 | D33: =IFERROR(__xludf.DUMMYFUNCTION("REGEXMATCH(A33,""(?i)ratio"")"),FALSE) -> FALSE | E33: =IFERROR(__xludf.DUMMYFUNCTION("REGEXMATCH(A33,""(?i)relationship"")"),FALSE) -> FALSE | H33: AtomicUnit,ElectricField | N33: =if(isblank(M33),"",hyperlink("https://www.wikidata.org/wiki/"&M33,M33))
A34: AtomicUnitOfElectricFieldGradient | B34: =VLOOKUP(A34,Quantities!A:B,2,false) -> Atomic Unit Of Electric Field Gradient | C34: =countif(Quantities!A:A,A34) -> 1 | D34: =IFERROR(__xludf.DUMMYFUNCTION("REGEXMATCH(A34,""(?i)ratio"")"),FALSE) -> FALSE | E34: =IFERROR(__xludf.DUMMYFUNCTION("REGEXMATCH(A34,""(?i)relationship"")"),FALSE) -> FALSE | H34: AtomicUnit,ElectricFieldGradient | N34: =if(isblank(M34),"",hyperlink("https://www.wikidata.org/wiki/"&M34,M34))
A35: AtomicUnitOfElectricPolarizability | B35: =VLOOKUP(A35,Quantities!A:B,2,false) -> Atomic Unit Of Electric Polarizability | C35: =countif(Quantities!A:A,A35) -> 1 | D35: =IFERROR(__xludf.DUMMYFUNCTION("REGEXMATCH(A35,""(?i)ratio"")"),FALSE) -> FALSE | E35: =IFERROR(__xludf.DUMMYFUNCTION("REGEXMATCH(A35,""(?i)relationship"")"),FALSE) -> FALSE | H35: AtomicUnit,ElectricPolarizability | N35: =if(isblank(M35),"",hyperlink("https://www.wikidata.org/wiki/"&M35,M35))
A36: AtomicUnitOfElectricPotential | B36: =VLOOKUP(A36,Quantities!A:B,2,false) -> Atomic Unit Of Electric Potential | C36: =countif(Quantities!A:A,A36) -> 1 | D36: =IFERROR(__xludf.DUMMYFUNCTION("REGEXMATCH(A36,""(?i)ratio"")"),FALSE) -> FALSE | E36: =IFERROR(__xludf.DUMMYFUNCTION("REGEXMATCH(A36,""(?i)relationship"")"),FALSE) -> FALSE | H36: AtomicUnit,ElectricPotential | N36: =if(isblank(M36),"",hyperlink("https://www.wikidata.org/wiki/"&M36,M36))
A37: AtomicUnitOfElectricQuadrupoleMoment | B37: =VLOOKUP(A37,Quantities!A:B,2,false) -> Atomic Unit Of Electric Quadrupole Moment | C37: =countif(Quantities!A:A,A37) -> 1 | D37: =IFERROR(__xludf.DUMMYFUNCTION("REGEXMATCH(A37,""(?i)ratio"")"),FALSE) -> FALSE | E37: =IFERROR(__xludf.DUMMYFUNCTION("REGEXMATCH(A37,""(?i)relationship"")"),FALSE) -> FALSE | H37: AtomicUnit,ElectricQuadrupoleMoment | N37: =if(isblank(M37),"",hyperlink("https://www.wikidata.org/wiki/"&M37,M37))
A38: AtomicUnitOfEnergy | B38: =VLOOKUP(A38,Quantities!A:B,2,false) -> Atomic Unit Of Energy | C38: =countif(Quantities!A:A,A38) -> 1 | D38: =IFERROR(__xludf.DUMMYFUNCTION("REGEXMATCH(A38,""(?i)ratio"")"),FALSE) -> FALSE | E38: =IFERROR(__xludf.DUMMYFUNCTION("REGEXMATCH(A38,""(?i)relationship"")"),FALSE) -> FALSE | H38: AtomicUnit,Energy | N38: =if(isblank(M38),"",hyperlink("https://www.wikidata.org/wiki/"&M38,M38))
A39: AtomicUnitOfForce | B39: =VLOOKUP(A39,Quantities!A:B,2,false) -> Atomic Unit Of Force | C39: =countif(Quantities!A:A,A39) -> 1 | D39: =IFERROR(__xludf.DUMMYFUNCTION("REGEXMATCH(A39,""(?i)ratio"")"),FALSE) -> FALSE | E39: =IFERROR(__xludf.DUMMYFUNCTION("REGEXMATCH(A39,""(?i)relationship"")"),FALSE) -> FALSE | H39: AtomicUnit,Force | N39: =if(isblank(M39),"",hyperlink("https://www.wikidata.org/wiki/"&M39,M39))
A40: AtomicUnitOfLength | B40: =VLOOKUP(A40,Quantities!A:B,2,false) -> Atomic Unit Of Length | C40: =countif(Quantities!A:A,A40) -> 1 | D40: =IFERROR(__xludf.DUMMYFUNCTION("REGEXMATCH(A40,""(?i)ratio"")"),FALSE) -> FALSE | E40: =IFERROR(__xludf.DUMMYFUNCTION("REGEXMATCH(A40,""(?i)relationship"")"),FALSE) -> FALSE | H40: AtomicUnit,Length | N40: =if(isblank(M40),"",hyperlink("https://www.wikidata.org/wiki/"&M40,M40))
...

Sheet Quantities
A1: id | B1: name | C1: notation | D1: has_concept | E1: n_constants | F1: uri
A2: AlphaParticleElectronMassRatio | B2: Alpha Particle - Electron Mass Ratio | D2: =COUNTIF(Concepts!A:A,A2) -> 1 | E2: =countif(Constants!J:J,$A2) -> 1 | F2: =CONCATENATE("https://w3ids.org/codata/fundamental/quantities/",A2) -> https://w3ids.org/codata/fundamental/quantities/AlphaParticleElectronMassRatio
A3: AlphaParticleMass | B3: Alpha Particle Mass | D3: =COUNTIF(Concepts!A:A,A3) -> 1 | E3: =countif(Constants!J:J,$A3) -> 2 | F3: =CONCATENATE("https://w3ids.org/codata/fundamental/quantities/",A3) -> https://w3ids.org/codata/fundamental/quantities/AlphaParticleMass
A4: AlphaParticleMassEnergyEquivalent | B4: Alpha Particle Mass Energy Equivalent | D4: =COUNTIF(Concepts!A:A,A4) -> 1 | E4: =countif(Constants!J:J,$A4) -> 2 | F4: =CONCATENATE("https://w3ids.org/codata/fundamental/quantities/",A4) -> https://w3ids.org/codata/fundamental/quantities/AlphaParticleMassEnergyEquivalent
A5: AlphaParticleMolarMass | B5: Alpha Particle Molar Mass | D5: =COUNTIF(Concepts!A:A,A5) -> 1 | E5: =countif(Constants!J:J,$A5) -> 1 | F5: =CONCATENATE("https://w3ids.org/codata/fundamental/quantities/",A5) -> https://w3ids.org/codata/fundamental/quantities/AlphaParticleMolarMass
A6: AlphaParticleProtonMassRatio | B6: Alpha Particle - Proton Mass Ratio | D6: =COUNTIF(Concepts!A:A,A6) -> 1 | E6: =countif(Constants!J:J,$A6) -> 1 | F6: =CONCATENATE("https://w3ids.org/codata/fundamental/quantities/",A6) -> https://w3ids.org/codata/fundamental/quantities/AlphaParticleProtonMassRatio
A7: AlphaParticleRelativeAtomicMass | B7: Alpha Particle Relative Atomic Mass | D7: =COUNTIF(Concepts!A:A,A7) -> 1 | E7: =countif(Constants!J:J,$A7) -> 1 | F7: =CONCATENATE("https://w3ids.org/codata/fundamental/quantities/",A7) -> https://w3ids.org/codata/fundamental/quantities/AlphaParticleRelativeAtomicMass
A8: AlphaParticleRmsChargeRadius | B8: Alpha Particle Rms Charge Radius | D8: =COUNTIF(Concepts!A:A,A8) -> 1 | E8: =countif(Constants!J:J,$A8) -> 1 | F8: =CONCATENATE("https://w3ids.org/codata/fundamental/quantities/",A8) -> https://w3ids.org/codata/fundamental/quantities/AlphaParticleRmsChargeRadius
A9: AngstromStar | B9: Angstrom Star | C9: Å* | D9: =COUNTIF(Concepts!A:A,A9) -> 1 | E9: =countif(Constants!J:J,$A9) -> 1 | F9: =CONCATENATE("https://w3ids.org/codata/fundamental/quantities/",A9) -> https://w3ids.org/codata/fundamental/quantities/AngstromStar
A10: AtomicMassConstant | B10: Atomic Mass Constant | D10: =COUNTIF(Concepts!A:A,A10) -> 1 | E10: =countif(Constants!J:J,$A10) -> 1 | F10: =CONCATENATE("https://w3ids.org/codata/fundamental/quantities/",A10) -> https://w3ids.org/codata/fundamental/quantities/AtomicMassConstant
A11: AtomicMassConstantEnergyEquivalent | B11: Atomic Mass Constant Energy Equivalent | D11: =COUNTIF(Concepts!A:A,A11) -> 1 | E11: =countif(Constants!J:J,$A11) -> 2 | F11: =CONCATENATE("https://w3ids.org/codata/fundamental/quantities/",A11) -> https://w3ids.org/codata/fundamental/quantities/AtomicMassConstantEnergyEquivalent
A12: AtomicMassUnitElectronVoltRelationship | B12: Atomic Mass Unit - Electronvolt Relationship | D12: =COUNTIF(Concepts!A:A,A12) -> 1 | E12: =countif(Constants!J:J,$A12) -> 1 | F12: =CONCATENATE("https://w3ids.org/codata/fundamental/quantities/",A12) -> https://w3ids.org/codata/fundamental/quantities/AtomicMassUnitElectronVoltRelationship
A13: AtomicMassUnitHartreeRelationship | B13: Atomic Mass Unit - Hartree Relationship | D13: =COUNTIF(Concepts!A:A,A13) -> 1 | E13: =countif(Constants!J:J,$A13) -> 1 | F13: =CONCATENATE("https://w3ids.org/codata/fundamental/quantities/",A13) -> https://w3ids.org/codata/fundamental/quantities/AtomicMassUnitHartreeRelationship
A14: AtomicMassUnitHertzRelationship | B14: Atomic Mass Unit - Hertz Relationship | D14: =COUNTIF(Concepts!A:A,A14) -> 1 | E14: =countif(Constants!J:J,$A14) -> 1 | F14: =CONCATENATE("https://w3ids.org/codata/fundamental/quantities/",A14) -> https://w3ids.org/codata/fundamental/quantities/AtomicMassUnitHertzRelationship
A15: AtomicMassUnitInverseMeterRelationship | B15: Atomic Mass Unit - Inverse Meter Relationship | D15: =COUNTIF(Concepts!A:A,A15) -> 1 | E15: =countif(Constants!J:J,$A15) -> 1 | F15: =CONCATENATE("https://w3ids.org/codata/fundamental/quantities/",A15) -> https://w3ids.org/codata/fundamental/quantities/AtomicMassUnitInverseMeterRelationship
A16: AtomicMassUnitJouleRelationship | B16: Atomic Mass Unit - Joule Relationship | D16: =COUNTIF(Concepts!A:A,A16) -> 1 | E16: =countif(Constants!J:J,$A16) -> 1 | F16: =CONCATENATE("https://w3ids.org/codata/fundamental/quantities/",A16) -> https://w3ids.org/codata/fundamental/quantities/AtomicMassUnitJouleRelationship
A17: AtomicMassUnitKelvinRelationship | B17: Atomic Mass Unit - Kelvin Relationship | D17: =COUNTIF(Concepts!A:A,A17) -> 1 | E17: =countif(Constants!J:J,$A17) -> 1 | F17: =CONCATENATE("https://w3ids.org/codata/fundamental/quantities/",A17) -> https://w3ids.org/codata/fundamental/quantities/AtomicMassUnitKelvinRelationship
A18: AtomicMassUnitKilogramRelationship | B18: Atomic Mass Unit - Kilogram Relationship | D18: =COUNTIF(Concepts!A:A,A18) -> 1 | E18: =countif(Constants!J:J,$A18) -> 1 | F18: =CONCATENATE("https://w3ids.org/codata/fundamental/quantities/",A18) -> https://w3ids.org/codata/fundamental/quantities/AtomicMassUnitKilogramRelationship
A19: AtomicUnitOf1stHyperpolarizability | B19: Atomic Unit Of First Hyperpolarizability | D19: =COUNTIF(Concepts!A:A,A19) -> 1 | E19: =countif(Constants!J:J,$A19) -> 1 | F19: =CONCATENATE("https://w3ids.org/codata/fundamental/quantities/",A19) -> https://w3ids.org/codata/fundamental/quantities/AtomicUnitOf1stHyperpolarizability
A20: AtomicUnitOf2ndHyperpolarizability | B20: Atomic Unit Of Second Hyperpolarizability | D20: =COUNTIF(Concepts!A:A,A20) -> 1 | E20: =countif(Constants!J:J,$A20) -> 1 | F20: =CONCATENATE("https://w3ids.org/codata/fundamental/quantities/",A20) -> https://w3ids.org/codata/fundamental/quantities/AtomicUnitOf2ndHyperpolarizability
A21: AtomicUnitOfAction | B21: Atomic Unit Of Action | D21: =COUNTIF(Concepts!A:A,A21) -> 1 | E21: =countif(Constants!J:J,$A21) -> 1 | F21: =CONCATENATE("https://w3ids.org/codata/fundamental/quantities/",A21) -> https://w3ids.org/codata/fundamental/quantities/AtomicUnitOfAction
... A140: HertzKilogramRelationship | B140: Hertz - Kilogram Relationship | D140: =COUNTIF(Concepts!A:A,A140) -> 1 | E140: =countif(Constants!J:J,$A140) -> 1 | F140: =CONCATENATE("https://w3ids.org/codata/fundamental/quantities/",A140) -> https://w3ids.org/codata/fundamental/quantities/HertzKilogramRelationship
A141: HyperfineTransitionFrequencyOfCs133 | B141: Hyperfine Transition Frequency Of Cs-133 | C141: (\(\Delta \nu _{Cs}\) | D141: =COUNTIF(Concepts!A:A,A141) -> 1 | E141: =countif(Constants!J:J,$A141) -> 1 | F141: =CONCATENATE("https://w3ids.org/codata/fundamental/quantities/",A141) -> https://w3ids.org/codata/fundamental/quantities/HyperfineTransitionFrequencyOfCs133
A142: InverseFineStructureConstant | B142: Inverse Fine-Structure Constant | D142: =COUNTIF(Concepts!A:A,A142) -> 1 | E142: =countif(Constants!J:J,$A142) -> 1 | F142: =CONCATENATE("https://w3ids.org/codata/fundamental/quantities/",A142) -> https://w3ids.org/codata/fundamental/quantities/InverseFineStructureConstant
A143: InverseMeterAtomicMassUnitRelationship | B143: Inverse Meter - Atomic Mass Unit Relationship | D143: =COUNTIF(Concepts!A:A,A143) -> 1 | E143: =countif(Constants!J:J,$A143) -> 1 | F143: =CONCATENATE("https://w3ids.org/codata/fundamental/quantities/",A143) -> https://w3ids.org/codata/fundamental/quantities/InverseMeterAtomicMassUnitRelationship
A144: InverseMeterElectronVoltRelationship | B144: Inverse Meter - Electronvolt Relationship | D144: =COUNTIF(Concepts!A:A,A144) -> 1 | E144: =countif(Constants!J:J,$A144) -> 1 | F144: =CONCATENATE("https://w3ids.org/codata/fundamental/quantities/",A144) -> https://w3ids.org/codata/fundamental/quantities/InverseMeterElectronVoltRelationship
A145: InverseMeterHartreeRelationship | B145: Inverse Meter-Hartree Relationship | D145: =COUNTIF(Concepts!A:A,A145) -> 1 | E145: =countif(Constants!J:J,$A145) -> 1 | F145: =CONCATENATE("https://w3ids.org/codata/fundamental/quantities/",A145) -> https://w3ids.org/codata/fundamental/quantities/InverseMeterHartreeRelationship
A146: InverseMeterHertzRelationship | B146: Inverse Meter - Hertz Relationship | D146: =COUNTIF(Concepts!A:A,A146) -> 1 | E146: =countif(Constants!J:J,$A146) -> 1 | F146: =CONCATENATE("https://w3ids.org/codata/fundamental/quantities/",A146) -> https://w3ids.org/codata/fundamental/quantities/InverseMeterHertzRelationship
A147: InverseMeterJouleRelationship | B147: Inverse Meter - Joule Relationship | D147: =COUNTIF(Concepts!A:A,A147) -> 1 | E147: =countif(Constants!J:J,$A147) -> 1 | F147: =CONCATENATE("https://w3ids.org/codata/fundamental/quantities/",A147) -> https://w3ids.org/codata/fundamental/quantities/InverseMeterJouleRelationship
A148: InverseMeterKelvinRelationship | B148: Inverse Meter - Kelvin Relationship | D148: =COUNTIF(Concepts!A:A,A148) -> 1 | E148: =countif(Constants!J:J,$A148) -> 1 | F148: =CONCATENATE("https://w3ids.org/codata/fundamental/quantities/",A148) -> https://w3ids.org/codata/fundamental/quantities/InverseMeterKelvinRelationship
A149: InverseMeterKilogramRelationship | B149: Inverse Meter - Kilogram Relationship | D149: =COUNTIF(Concepts!A:A,A149) -> 1 | E149: =countif(Constants!J:J,$A149) -> 1 | F149: =CONCATENATE("https://w3ids.org/codata/fundamental/quantities/",A149) -> https://w3ids.org/codata/fundamental/quantities/InverseMeterKilogramRelationship
A150: InverseOfConductanceQuantum | B150: Inverse Of Conductance Quantum | D150: =COUNTIF(Concepts!A:A,A150) -> 1 | E150: =countif(Constants!J:J,$A150) -> 1 | F150: =CONCATENATE("https://w3ids.org/codata/fundamental/quantities/",A150) -> https://w3ids.org/codata/fundamental/quantities/InverseOfConductanceQuantum
A151: JosephsonConstant | B151: Josephson Constant | D151: =COUNTIF(Concepts!A:A,A151) -> 1 | E151: =countif(Constants!J:J,$A151) -> 1 | F151: =CONCATENATE("https://w3ids.org/codata/fundamental/quantities/",A151) -> https://w3ids.org/codata/fundamental/quantities/JosephsonConstant
A152: JouleAtomicMassUnitRelationship | B152: Joule - Atomic Mass Unit Relationship | D152: =COUNTIF(Concepts!A:A,A152) -> 1 | E152: =countif(Constants!J:J,$A152) -> 1 | F152: =CONCATENATE("https://w3ids.org/codata/fundamental/quantities/",A152) -> https://w3ids.org/codata/fundamental/quantities/JouleAtomicMassUnitRelationship
A153: JouleElectronVoltRelationship | B153: Joule - Electronvolt Relationship | D153: =COUNTIF(Concepts!A:A,A153) -> 1 | E153: =countif(Constants!J:J,$A153) -> 1 | F153: =CONCATENATE("https://w3ids.org/codata/fundamental/quantities/",A153) -> https://w3ids.org/codata/fundamental/quantities/JouleElectronVoltRelationship
... A274: ShieldingDifferenceOfTAndP | B274: Shielding Difference Of T And P In Ht | D274: =COUNTIF(Concepts!A:A,A274) -> 1 | E274: =countif(Constants!J:J,$A274) -> 1 | F274: =CONCATENATE("https://w3ids.org/codata/fundamental/quantities/",A274) -> https://w3ids.org/codata/fundamental/quantities/ShieldingDifferenceOfTAndP
A275: SpeedOfLight | B275: Speed Of Light In Vacuum | C275: (\(c\)) | D275: =COUNTIF(Concepts!A:A,A275) -> 1 | E275: =countif(Constants!J:J,$A275) -> 1 | F275: =CONCATENATE("https://w3ids.org/codata/fundamental/quantities/",A275) -> https://w3ids.org/codata/fundamental/quantities/SpeedOfLight
A276: StandardAccelerationOfGravity | B276: Standard Acceleration Of Gravity | D276: =COUNTIF(Concepts!A:A,A276) -> 1 | E276: =countif(Constants!J:J,$A276) -> 1 | F276: =CONCATENATE("https://w3ids.org/codata/fundamental/quantities/",A276) -> https://w3ids.org/codata/fundamental/quantities/StandardAccelerationOfGravity
A277: StandardAtmosphere | B277: Standard Atmosphere | D277: =COUNTIF(Concepts!A:A,A277) -> 1 | E277: =countif(Constants!J:J,$A277) -> 1 | F277: =CONCATENATE("https://w3ids.org/codata/fundamental/quantities/",A277) -> https://w3ids.org/codata/fundamental/quantities/StandardAtmosphere
A278: StandardStatePressure | B278: Standard-State Pressure | D278: =COUNTIF(Concepts!A:A,A278) -> 1 | E278: =countif(Constants!J:J,$A278) -> 1 | F278: =CONCATENATE("https://w3ids.org/codata/fundamental/quantities/",A278) -> https://w3ids.org/codata/fundamental/quantities/StandardStatePressure
...

Sheet Constants
A1: nist_id | B1: id | C1: name | D1: name_fr | E1: name_bipm_en | F1: name_bipm_fr | G1: unit_nist | H1: unit_id | I1: unit_id_lookup | J1: quantity_id | K1: quantity_id_lookup | L1: is_base | M1: qudt_id | N1: qudt_url | O1: is_qudt | P1: ucum_id | Q1: si_id | R1: si_url | S1: versions | T1: is_2022 | U1: is_2018 | V1: is_2014 | W1: is_2010 | X1: is_2006 | Y1: is_2002 | Z1: is_1998
A2: malsme | B2: AlphaParticleElectronMassRatio | C2: =proper(E2) -> Alpha Particle - Electron Mass Ratio | D2: =UPPER(LEFT(F2,1))&MID(F2,2,LEN(F2)) -> Rapport de la masse de la particule alpha à celle de l'électron | E2: alpha particle - electron mass ratio | F2: rapport de la masse de la particule alpha à celle de l'électron | H2: =if(ISBLANK(G2),"",SUBSTITUTE(SUBSTITUTE(G2,"^","")," ","_")) | I2: =if(H2="","", countif(Units!A:A,H2)) | J2: AlphaParticleElectronMassRatio | K2: =countif(Quantities!A:A,J2) -> 1 | L2: =J2=B2 -> TRUE | M2: AlphaParticleElectronMassRatio | N2: =if(isblank(M2),"",hyperlink("https://qudt.org/vocab/constant/"&M2&".html","qudt")) -> qudt | O2: =not(isblank(M2)) -> TRUE | R2: =if(isblank(Q2),"",hyperlink("https://si-digital-framework.org/constants/"&Q2,"SI")) | S2: =sum(T2:Z2) -> 7 | T2: =countif('v2022'!E:E,A2) -> 1 | U2: =countif('v2018'!E:E,A2) -> 1 | V2: =countif('v2014'!E:E,A2) -> 1 | W2: =countif('v2010'!E:E,A2) -> 1 | X2: =countif('v2006'!E:E,A2) -> 1 | Y2: =countif('v2002'!E:E,A2) -> 1 | Z2: =countif('v1998'!E:E,A2) -> 1
A3: mal | B3: AlphaParticleMass | C3: =proper(E3) -> Alpha Particle Mass | D3: =UPPER(LEFT(F3,1))&MID(F3,2,LEN(F3)) -> Masse de la particule alpha | E3: alpha particle mass | F3: masse de la particule alpha | G3: kg | H3: =if(ISBLANK(G3),"",SUBSTITUTE(SUBSTITUTE(G3,"^","")," ","_")) -> kg | I3: =if(H3="","", countif(Units!A:A,H3)) -> 1 | J3: AlphaParticleMass | K3: =countif(Quantities!A:A,J3) -> 1 | L3: =J3=B3 -> TRUE | M3: AlphaParticleMass | N3: =if(isblank(M3),"",hyperlink("https://qudt.org/vocab/constant/"&M3&".html","qudt")) -> qudt | O3: =not(isblank(M3)) -> TRUE | R3: =if(isblank(Q3),"",hyperlink("https://si-digital-framework.org/constants/"&Q3,"SI")) | S3: =sum(T3:Z3) -> 7 | T3: =countif('v2022'!E:E,A3) -> 1 | U3: =countif('v2018'!E:E,A3) -> 1 | V3: =countif('v2014'!E:E,A3) -> 1 | W3: =countif('v2010'!E:E,A3) -> 1 | X3: =countif('v2006'!E:E,A3) -> 1 | Y3: =countif('v2002'!E:E,A3) -> 1 | Z3: =countif('v1998'!E:E,A3) -> 1
A4: malc2 | B4: AlphaParticleMassEnergyEquivalent | C4: =proper(E4) -> Alpha Particle Mass Energy Equivalent | D4: =UPPER(LEFT(F4,1))&MID(F4,2,LEN(F4)) -> Énergie de masse de la particule alpha | E4: alpha particle mass energy equivalent | F4: énergie de masse de la particule alpha | G4: J | H4: =if(ISBLANK(G4),"",SUBSTITUTE(SUBSTITUTE(G4,"^","")," ","_")) -> J | I4: =if(H4="","", countif(Units!A:A,H4)) -> 1 | J4: AlphaParticleMassEnergyEquivalent | K4: =countif(Quantities!A:A,J4) -> 1 | L4: =J4=B4 -> TRUE | M4: AlphaParticleMassEnergyEquivalent | N4: =if(isblank(M4),"",hyperlink("https://qudt.org/vocab/constant/"&M4&".html","qudt")) -> qudt | O4: =not(isblank(M4)) -> TRUE | R4: =if(isblank(Q4),"",hyperlink("https://si-digital-framework.org/constants/"&Q4,"SI")) | S4: =sum(T4:Z4) -> 7 | T4: =countif('v2022'!E:E,A4) -> 1 | U4: =countif('v2018'!E:E,A4) -> 1 | V4: =countif('v2014'!E:E,A4) -> 1 | W4: =countif('v2010'!E:E,A4) -> 1 | X4: =countif('v2006'!E:E,A4) -> 1 | Y4: =countif('v2002'!E:E,A4) -> 1 | Z4: =countif('v1998'!E:E,A4) -> 1
A5: malc2mev | B5: AlphaParticleMassEnergyEquivalentInMeV | C5: Alpha Particle Mass Energy Equivalent In MeV | D5: =UPPER(LEFT(F5,1))&MID(F5,2,LEN(F5)) -> Énergie de masse de la particule alpha in MeV | E5: alpha particle mass energy equivalent in MeV | F5: énergie de masse de la particule alpha in MeV | G5: MeV | H5: =if(ISBLANK(G5),"",SUBSTITUTE(SUBSTITUTE(G5,"^","")," ","_")) -> MeV | I5: =if(H5="","", countif(Units!A:A,H5)) -> 1 | J5: AlphaParticleMassEnergyEquivalent | K5: =countif(Quantities!A:A,J5) -> 1 | L5: =J5=B5 -> FALSE | M5: AlphaParticleMassEnergyEquivalentInMeV | N5: =if(isblank(M5),"",hyperlink("https://qudt.org/vocab/constant/"&M5&".html","qudt")) -> qudt | O5: =not(isblank(M5)) -> TRUE | R5: =if(isblank(Q5),"",hyperlink("https://si-digital-framework.org/constants/"&Q5,"SI")) | S5: =sum(T5:Z5) -> 7 | T5: =countif('v2022'!E:E,A5) -> 1 | U5: =countif('v2018'!E:E,A5) -> 1 | V5: =countif('v2014'!E:E,A5) -> 1 | W5: =countif('v2010'!E:E,A5) -> 1 | X5: =countif('v2006'!E:E,A5) -> 1 | Y5: =countif('v2002'!E:E,A5) -> 1 | Z5: =countif('v1998'!E:E,A5) -> 1
A6: malu | B6: AlphaParticleMassInAtomicMassUnit | C6: =proper(E6) -> Alpha Particle Mass In U | D6: =UPPER(LEFT(F6,1))&MID(F6,2,LEN(F6)) -> Masse de la particule alpha en u | E6: alpha particle mass in u | F6: masse de la particule alpha en u | G6: u | H6: =if(ISBLANK(G6),"",SUBSTITUTE(SUBSTITUTE(G6,"^","")," ","_")) -> u | I6: =if(H6="","", countif(Units!A:A,H6)) -> 1 | J6: AlphaParticleMass | K6: =countif(Quantities!A:A,J6) -> 1 | L6: =J6=B6 -> FALSE | M6: AlphaParticleMassInAtomicMassUnit | N6: =if(isblank(M6),"",hyperlink("https://qudt.org/vocab/constant/"&M6&".html","qudt")) -> qudt | O6: =not(isblank(M6)) -> TRUE | R6: =if(isblank(Q6),"",hyperlink("https://si-digital-framework.org/constants/"&Q6,"SI")) | S6: =sum(T6:Z6) -> 7 | T6: =countif('v2022'!E:E,A6) -> 1 | U6: =countif('v2018'!E:E,A6) -> 1 | V6: =countif('v2014'!E:E,A6) -> 1 | W6: =countif('v2010'!E:E,A6) -> 1 | X6: =countif('v2006'!E:E,A6) -> 1 | Y6: =countif('v2002'!E:E,A6) -> 1 | Z6: =countif('v1998'!E:E,A6) -> 1
A7: mmal | B7: AlphaParticleMolarMass | C7: =proper(E7) -> Alpha Particle Molar Mass | D7: =UPPER(LEFT(F7,1))&MID(F7,2,LEN(F7)) -> Masse molaire de la particule alpha | E7: alpha particle molar mass | F7: masse molaire de la particule alpha | G7: kg mol^-1 | H7: =if(ISBLANK(G7),"",SUBSTITUTE(SUBSTITUTE(G7,"^","")," ","_")) -> kg_mol-1 | I7: =if(H7="","", countif(Units!A:A,H7)) -> 1 | J7: AlphaParticleMolarMass | K7: =countif(Quantities!A:A,J7) -> 1 | L7: =J7=B7 -> TRUE | M7: AlphaParticleMolarMass | N7: =if(isblank(M7),"",hyperlink("https://qudt.org/vocab/constant/"&M7&".html","qudt")) -> qudt | O7: =not(isblank(M7)) -> TRUE | R7: =if(isblank(Q7),"",hyperlink("https://si-digital-framework.org/constants/"&Q7,"SI")) | S7: =sum(T7:Z7) -> 7 | T7: =countif('v2022'!E:E,A7) -> 1 | U7: =countif('v2018'!E:E,A7) -> 1 | V7: =countif('v2014'!E:E,A7) -> 1 | W7: =countif('v2010'!E:E,A7) -> 1 | X7: =countif('v2006'!E:E,A7) -> 1 | Y7: =countif('v2002'!E:E,A7) -> 1 | Z7: =countif('v1998'!E:E,A7) -> 1
A8: malsmp | B8: AlphaParticleProtonMassRatio | C8: =proper(E8) -> Alpha Particle - Proton Mass Ratio | D8: =UPPER(LEFT(F8,1))&MID(F8,2,LEN(F8)) -> Rapport de la masse de la particule alpha à celle du proton | E8: alpha particle - proton mass ratio | F8: rapport de la masse de la particule alpha à celle du proton | H8: =if(ISBLANK(G8),"",SUBSTITUTE(SUBSTITUTE(G8,"^","")," ","_")) | I8: =if(H8="","", countif(Units!A:A,H8)) | J8: AlphaParticleProtonMassRatio | K8: =countif(Quantities!A:A,J8) -> 1 | L8: =J8=B8 -> TRUE | M8: AlphaParticleProtonMassRatio | N8: =if(isblank(M8),"",hyperlink("https://qudt.org/vocab/constant/"&M8&".html","qudt")) -> qudt | O8: =not(isblank(M8)) -> TRUE | R8: =if(isblank(Q8),"",hyperlink("https://si-digital-framework.org/constants/"&Q8,"SI")) | S8: =sum(T8:Z8) -> 7 | T8: =countif('v2022'!E:E,A8) -> 1 | U8: =countif('v2018'!E:E,A8) -> 1 | V8: =countif('v2014'!E:E,A8) -> 1 | W8: =countif('v2010'!E:E,A8) -> 1 | X8: =countif('v2006'!E:E,A8) -> 1 | Y8: =countif('v2002'!E:E,A8) -> 1 | Z8: =countif('v1998'!E:E,A8) -> 1
A9: aral | B9: AlphaParticleRelativeAtomicMass | C9: =proper(E9) -> Alpha Particle Relative Atomic Mass | D9: =proper(F9) -> Rapport De La Masse De La Particule Alpha À Celle Du Proton | E9: alpha particle relative atomic mass | F9: rapport de la masse de la particule alpha à celle du proton | H9: =if(ISBLANK(G9),"",SUBSTITUTE(SUBSTITUTE(G9,"^","")," ","_")) | I9: =if(H9="","", countif(Units!A:A,H9)) | J9: AlphaParticleRelativeAtomicMass | K9: =countif(Quantities!A:A,J9) -> 1 | L9: =J9=B9 -> TRUE | N9: =if(isblank(M9),"",hyperlink("https://qudt.org/vocab/constant/"&M9&".html","qudt")) | O9: =not(isblank(M9)) -> FALSE | R9: =if(isblank(Q9),"",hyperlink("https://si-digital-framework.org/constants/"&Q9,"SI")) | S9: =sum(T9:Z9) -> 2 | T9: =countif('v2022'!E:E,A9) -> 1 | U9: =countif('v2018'!E:E,A9) -> 1 | V9: =countif('v2014'!E:E,A9) -> 0 | W9: =countif('v2010'!E:E,A9) -> 0 | X9: =countif('v2006'!E:E,A9) -> 0 | Y9: =countif('v2002'!E:E,A9) -> 0 | Z9: =countif('v1998'!E:E,A9) -> 0
A10: ral | B10: AlphaParticleRmsChargeRadius | C10: =proper(E10) -> Alpha Particle Rms Charge Radius | D10: =UPPER(LEFT(F10,1))&MID(F10,2,LEN(F10)) -> Rayon de charge effectif de l aparticule alpha | E10: alpha particle rms charge radius | F10: rayon de charge effectif de l aparticule alpha | H10: =if(ISBLANK(G10),"",SUBSTITUTE(SUBSTITUTE(G10,"^","")," ","_")) | I10: =if(H10="","", countif(Units!A:A,H10)) | J10: AlphaParticleRmsChargeRadius | K10: =countif(Quantities!A:A,J10) -> 1 | L10: =J10=B10 -> TRUE | N10: =if(isblank(M10),"",hyperlink("https://qudt.org/vocab/constant/"&M10&".html","qudt")) | O10: =not(isblank(M10)) -> FALSE | R10: =if(isblank(Q10),"",hyperlink("https://si-digital-framework.org/constants/"&Q10,"SI")) | S10: =sum(T10:Z10) -> 1 | T10: =countif('v2022'!E:E,A10) -> 1 | U10: =countif('v2018'!E:E,A10) -> 0 | V10: =countif('v2014'!E:E,A10) -> 0 | W10: =countif('v2010'!E:E,A10) -> 0 | X10: =countif('v2006'!E:E,A10) -> 0 | Y10: =countif('v2002'!E:E,A10) -> 0 | Z10: =countif('v1998'!E:E,A10) -> 0
A11: angstar | B11: AngstromStar | C11: =proper(E11) -> Angstrom Star | D11: =UPPER(LEFT(F11,1))&MID(F11,2,LEN(F11)) -> Ångström étoile | E11: Angstrom star | F11: ångström étoile | G11: m | H11: =if(ISBLANK(G11),"",SUBSTITUTE(SUBSTITUTE(G11,"^","")," ","_")) -> m | I11: =if(H11="","", countif(Units!A:A,H11)) -> 1 | J11: AngstromStar | K11: =countif(Quantities!A:A,J11) -> 1 | L11: =J11=B11 -> TRUE | M11: AngstromStar | N11: =if(isblank(M11),"",hyperlink("https://qudt.org/vocab/constant/"&M11&".html","qudt")) -> qudt | O11: =not(isblank(M11)) -> TRUE | R11: =if(isblank(Q11),"",hyperlink("https://si-digital-framework.org/constants/"&Q11,"SI")) | S11: =sum(T11:Z11) -> 7 | T11: =countif('v2022'!E:E,A11) -> 1 | U11: =countif('v2018'!E:E,A11) -> 1 | V11: =countif('v2014'!E:E,A11) -> 1 | W11: =countif('v2010'!E:E,A11) -> 1 | X11: =countif('v2006'!E:E,A11) -> 1 | Y11: =countif('v2002'!E:E,A11) -> 1 | Z11: =countif('v1998'!E:E,A11) -> 1
A12: u | B12: AtomicMassConstant | C12: =proper(E12) -> Atomic Mass Constant | D12: =UPPER(LEFT(F12,1))&MID(F12,2,LEN(F12)) -> Constante de masse atomique | E12: atomic mass constant | F12: constante de masse atomique | G12: kg | H12: =if(ISBLANK(G12),"",SUBSTITUTE(SUBSTITUTE(G12,"^","")," ","_")) -> kg | I12: =if(H12="","", countif(Units!A:A,H12)) -> 1 | J12: AtomicMassConstant | K12: =countif(Quantities!A:A,J12) -> 1 | L12: =J12=B12 -> TRUE | M12: AtomicMassConstant | N12: =if(isblank(M12),"",hyperlink("https://qudt.org/vocab/constant/"&M12&".html","qudt")) -> qudt | O12: =not(isblank(M12)) -> TRUE | R12: =if(isblank(Q12),"",hyperlink("https://si-digital-framework.org/constants/"&Q12,"SI")) | S12: =sum(T12:Z12) -> 7 | T12: =countif('v2022'!E:E,A12) -> 1 | U12: =countif('v2018'!E:E,A12) -> 1 | V12: =countif('v2014'!E:E,A12) -> 1 | W12: =countif('v2010'!E:E,A12) -> 1 | X12: =countif('v2006'!E:E,A12) -> 1 | Y12: =countif('v2002'!E:E,A12) -> 1 | Z12: =countif('v1998'!E:E,A12) -> 1
A13: muc2mev | B13: AtomicMassConstantEnergyEquivalentInMeV | C13: Atomic Mass Constant Energy Equivalent In MeV | D13: =UPPER(LEFT(F13,1))&MID(F13,2,LEN(F13)) -> Énergie équivalente à la constante de masse atomique | E13: atomic mass constant energy equivalent in MeV | F13: énergie équivalente à la constante de masse atomique | G13: MeV | H13: =if(ISBLANK(G13),"",SUBSTITUTE(SUBSTITUTE(G13,"^","")," ","_")) -> MeV | I13: =if(H13="","", countif(Units!A:A,H13)) -> 1 | J13: AtomicMassConstantEnergyEquivalent | K13: =countif(Quantities!A:A,J13) -> 1 | L13: =J13=B13 -> FALSE | M13: AtomicMassConstantEnergyEquivalentInMeV | N13: =if(isblank(M13),"",hyperlink("https://qudt.org/vocab/constant/"&M13&".html","qudt")) -> qudt | O13: =not(isblank(M13)) -> TRUE | R13: =if(isblank(Q13),"",hyperlink("https://si-digital-framework.org/constants/"&Q13,"SI")) | S13: =sum(T13:Z13) -> 7 | T13: =countif('v2022'!E:E,A13) -> 1 | U13: =countif('v2018'!E:E,A13) -> 1 | V13: =countif('v2014'!E:E,A13) -> 1 | W13: =countif('v2010'!E:E,A13) -> 1 | X13: =countif('v2006'!E:E,A13) -> 1 | Y13: =countif('v2002'!E:E,A13) -> 1 | Z13: =countif('v1998'!E:E,A13) -> 1
A14: uev | B14: AtomicMassUnitElectronVoltRelationship | C14: =proper(E14) -> Atomic Mass Unit - Electronvolt Relationship | D14: =UPPER(LEFT(F14,1))&MID(F14,2,LEN(F14)) -> Relation entre l'unité de masse atomique et l'électronvolt | E14: atomic mass unit - electronvolt relationship | F14: relation entre l'unité de masse atomique et l'électronvolt | G14: eV | H14: =if(ISBLANK(G14),"",SUBSTITUTE(SUBSTITUTE(G14,"^","")," ","_")) -> eV | I14: =if(H14="","", countif(Units!A:A,H14)) -> 1 | J14: AtomicMassUnitElectronVoltRelationship | K14: =countif(Quantities!A:A,J14) -> 1 | L14: =J14=B14 -> TRUE | M14: AtomicMassUnitElectronVoltRelationship | N14: =if(isblank(M14),"",hyperlink("https://qudt.org/vocab/constant/"&M14&".html","qudt")) -> qudt | O14: =not(isblank(M14)) -> TRUE | R14: =if(isblank(Q14),"",hyperlink("https://si-digital-framework.org/constants/"&Q14,"SI")) | S14: =sum(T14:Z14) -> 7 | T14: =countif('v2022'!E:E,A14) -> 1 | U14: =countif('v2018'!E:E,A14) -> 1 | V14: =countif('v2014'!E:E,A14) -> 1 | W14: =countif('v2010'!E:E,A14) -> 1 | X14: =countif('v2006'!E:E,A14) -> 1 | Y14: =countif('v2002'!E:E,A14) -> 1 | Z14: =countif('v1998'!E:E,A14) -> 1
A15: uhr | B15: AtomicMassUnitHartreeRelationship | C15: =proper(E15) -> Atomic Mass Unit - Hartree Relationship | D15: =UPPER(LEFT(F15,1))&MID(F15,2,LEN(F15)) -> Relation entre l'unité de masse atomique et le hartree | E15: atomic mass unit - hartree relationship | F15: relation entre l'unité de masse atomique et le hartree | G15: E_h | H15: =if(ISBLANK(G15),"",SUBSTITUTE(SUBSTITUTE(G15,"^","")," ","_")) -> E_h | I15: =if(H15="","", countif(Units!A:A,H15)) -> 1 | J15: AtomicMassUnitHartreeRelationship | K15: =countif(Quantities!A:A,J15) -> 1 | L15: =J15=B15 -> TRUE | M15: AtomicMassUnitHartreeRelationship | N15: =if(isblank(M15),"",hyperlink("https://qudt.org/vocab/constant/"&M15&".html","qudt")) -> qudt | O15: =not(isblank(M15)) -> TRUE | R15: =if(isblank(Q15),"",hyperlink("https://si-digital-framework.org/constants/"&Q15,"SI")) | S15: =sum(T15:Z15) -> 7 | T15: =countif('v2022'!E:E,A15) -> 1 | U15: =countif('v2018'!E:E,A15) -> 1 | V15: =countif('v2014'!E:E,A15) -> 1 | W15: =countif('v2010'!E:E,A15) -> 1 | X15: =countif('v2006'!E:E,A15) -> 1 | Y15: =countif('v2002'!E:E,A15) -> 1 | Z15: =countif('v1998'!E:E,A15) -> 1
A16: uhz | B16: AtomicMassUnitHertzRelationship | C16: =proper(E16) -> Atomic Mass Unit - Hertz Relationship | D16: =UPPER(LEFT(F16,1))&MID(F16,2,LEN(F16)) -> Relation entre l'unité de masse atomique et le hertz | E16: atomic mass unit - hertz relationship | F16: relation entre l'unité de masse atomique et le hertz | G16: Hz | H16: =if(ISBLANK(G16),"",SUBSTITUTE(SUBSTITUTE(G16,"^","")," ","_")) -> Hz | I16: =if(H16="","", countif(Units!A:A,H16)) -> 1 | J16: AtomicMassUnitHertzRelationship | K16: =countif(Quantities!A:A,J16) -> 1 | L16: =J16=B16 -> TRUE | M16: AtomicMassUnitHertzRelationship | N16: =if(isblank(M16),"",hyperlink("https://qudt.org/vocab/constant/"&M16&".html","qudt")) -> qudt | O16: =not(isblank(M16)) -> TRUE | R16: =if(isblank(Q16),"",hyperlink("https://si-digital-framework.org/constants/"&Q16,"SI")) | S16: =sum(T16:Z16) -> 7 | T16: =countif('v2022'!E:E,A16) -> 1 | U16: =countif('v2018'!E:E,A16) -> 1 | V16: =countif('v2014'!E:E,A16) -> 1 | W16: =countif('v2010'!E:E,A16) -> 1 | X16: =countif('v2006'!E:E,A16) -> 1 | Y16: =countif('v2002'!E:E,A16) -> 1 | Z16: =countif('v1998'!E:E,A16) -> 1
A17: uminv | B17: AtomicMassUnitInverseMeterRelationship | C17: =proper(E17) -> Atomic Mass Unit - Inverse Meter Relationship | D17: =UPPER(LEFT(F17,1))&MID(F17,2,LEN(F17)) -> Relation entre l'unité de masse atomique et l'inverse du mètre | E17: atomic mass unit - inverse meter relationship | F17: relation entre l'unité de masse atomique et l'inverse du mètre | G17: m^-1 | H17: =if(ISBLANK(G17),"",SUBSTITUTE(SUBSTITUTE(G17,"^","")," ","_")) -> m-1 | I17: =if(H17="","", countif(Units!A:A,H17)) -> 1 | J17: AtomicMassUnitInverseMeterRelationship | K17: =countif(Quantities!A:A,J17) -> 1 | L17: =J17=B17 -> TRUE | M17: AtomicMassUnitInverseMeterRelationship | N17: =if(isblank(M17),"",hyperlink("https://qudt.org/vocab/constant/"&M17&".html","qudt")) -> qudt | O17: =not(isblank(M17)) -> TRUE | R17: =if(isblank(Q17),"",hyperlink("https://si-digital-framework.org/constants/"&Q17,"SI")) | S17: =sum(T17:Z17) -> 7 | T17: =countif('v2022'!E:E,A17) -> 1 | U17: =countif('v2018'!E:E,A17) -> 1 | V17: =countif('v2014'!E:E,A17) -> 1 | W17: =countif('v2010'!E:E,A17) -> 1 | X17: =countif('v2006'!E:E,A17) -> 1 | Y17: =countif('v2002'!E:E,A17) -> 1 | Z17: =countif('v1998'!E:E,A17) -> 1
A18: Ruj | B18: AtomicMassUnitJouleRelationship | C18: =proper(E18) -> Atomic Mass Unit - Joule Relationship | D18: =UPPER(LEFT(F18,1))&MID(F18,2,LEN(F18)) -> Relation entre l'unité de masse atomique et le joule | E18: atomic mass unit - joule relationship | F18: relation entre l'unité de masse atomique et le joule | G18: J | H18: =if(ISBLANK(G18),"",SUBSTITUTE(SUBSTITUTE(G18,"^","")," ","_")) -> J | I18: =if(H18="","", countif(Units!A:A,H18)) -> 1 | J18: AtomicMassUnitJouleRelationship | K18: =countif(Quantities!A:A,J18) -> 1 | L18: =J18=B18 -> TRUE | M18: AtomicMassUnitJouleRelationship | N18: =if(isblank(M18),"",hyperlink("https://qudt.org/vocab/constant/"&M18&".html","qudt")) -> qudt | O18: =not(isblank(M18)) -> TRUE | R18: =if(isblank(Q18),"",hyperlink("https://si-digital-framework.org/constants/"&Q18,"SI")) | S18: =sum(T18:Z18) -> 7 | T18: =countif('v2022'!E:E,A18) -> 1 | U18: =countif('v2018'!E:E,A18) -> 1 | V18: =countif('v2014'!E:E,A18) -> 1 | W18: =countif('v2010'!E:E,A18) -> 1 | X18: =countif('v2006'!E:E,A18) -> 1 | Y18: =countif('v2002'!E:E,A18) -> 1 | Z18: =countif('v1998'!E:E,A18) -> 1
A19: uj | B19: AtomicMassConstantEnergyEquivalent | C19: =proper(E19) -> Atomic Mass Constant Energy Equivalent | D19: =UPPER(LEFT(F19,1))&MID(F19,2,LEN(F19)) -> Énergie équivalente à la constante de masse atomique | E19: atomic mass constant energy equivalent | F19: énergie équivalente à la constante de masse atomique | G19: J | H19: =if(ISBLANK(G19),"",SUBSTITUTE(SUBSTITUTE(G19,"^","")," ","_")) -> J | I19: =if(H19="","", countif(Units!A:A,H19)) -> 1 | J19: AtomicMassConstantEnergyEquivalent | K19: =countif(Quantities!A:A,J19) -> 1 | L19: =J19=B19 -> TRUE | M19: AtomicMassConstantEnergyEquivalent | N19: =if(isblank(M19),"",hyperlink("https://qudt.org/vocab/constant/"&M19&".html","qudt")) -> qudt | O19: =not(isblank(M19)) -> TRUE | R19: =if(isblank(Q19),"",hyperlink("https://si-digital-framework.org/constants/"&Q19,"SI")) | S19: =sum(T19:Z19) -> 7 | T19: =countif('v2022'!E:E,A19) -> 1 | U19: =countif('v2018'!E:E,A19) -> 1 | V19: =countif('v2014'!E:E,A19) -> 1 | W19: =countif('v2010'!E:E,A19) -> 1 | X19: =countif('v2006'!E:E,A19) -> 1 | Y19: =countif('v2002'!E:E,A19) -> 1 | Z19: =countif('v1998'!E:E,A19) -> 1
A20: uk | B20: AtomicMassUnitKelvinRelationship | C20: =proper(E20) -> Atomic Mass Unit - Kelvin Relationship | D20: =UPPER(LEFT(F20,1))&MID(F20,2,LEN(F20)) -> Relation entre l'unité de masse atomique et le kelvin | E20: atomic mass unit - kelvin relationship | F20: relation entre l'unité de masse atomique et le kelvin | G20: K | H20: =if(ISBLANK(G20),"",SUBSTITUTE(SUBSTITUTE(G20,"^","")," ","_")) -> K | I20: =if(H20="","", countif(Units!A:A,H20)) -> 1 | J20: AtomicMassUnitKelvinRelationship | K20: =countif(Quantities!A:A,J20) -> 1 | L20: =J20=B20 -> TRUE | M20: AtomicMassUnitKelvinRelationship | N20: =if(isblank(M20),"",hyperlink("https://qudt.org/vocab/constant/"&M20&".html","qudt")) -> qudt | O20: =not(isblank(M20)) -> TRUE | R20: =if(isblank(Q20),"",hyperlink("https://si-digital-framework.org/constants/"&Q20,"SI")) | S20: =sum(T20:Z20) -> 7 | T20: =countif('v2022'!E:E,A20) -> 1 | U20: =countif('v2018'!E:E,A20) -> 1 | V20: =countif('v2014'!E:E,A20) -> 1 | W20: =countif('v2010'!E:E,A20) -> 1 | X20: =countif('v2006'!E:E,A20) -> 1 | Y20: =countif('v2002'!E:E,A20) -> 1 | Z20: =countif('v1998'!E:E,A20) -> 1
A21: Rukg | B21: AtomicMassUnitKilogramRelationship | C21: =proper(E21) -> Atomic Mass Unit - Kilogram Relationship | D21: =UPPER(LEFT(F21,1))&MID(F21,2,LEN(F21)) -> Relation entre l'unité de masse atomique et le kilogramme | E21: atomic mass unit - kilogram relationship | F21: relation entre l'unité de masse atomique et le kilogramme | G21: kg | H21: =if(ISBLANK(G21),"",SUBSTITUTE(SUBSTITUTE(G21,"^","")," ","_")) -> kg | I21: =if(H21="","", countif(Units!A:A,H21)) -> 1 | J21: AtomicMassUnitKilogramRelationship | K21: =countif(Quantities!A:A,J21) -> 1 | L21: =J21=B21 -> TRUE | M21: AtomicMassUnitKilogramRelationship | N21: =if(isblank(M21),"",hyperlink("https://qudt.org/vocab/constant/"&M21&".html","qudt")) -> qudt | O21: =not(isblank(M21)) -> TRUE | R21: =if(isblank(Q21),"",hyperlink("https://si-digital-framework.org/constants/"&Q21,"SI")) | S21: =sum(T21:Z21) -> 7 | T21: =countif('v2022'!E:E,A21) -> 1 | U21: =countif('v2018'!E:E,A21) -> 1 | V21: =countif('v2014'!E:E,A21) -> 1 | W21: =countif('v2010'!E:E,A21) -> 1 | X21: =countif('v2006'!E:E,A21) -> 1 | Y21: =countif('v2002'!E:E,A21) -> 1 | Z21: =countif('v1998'!E:E,A21) -> 1
A22: auhypol | B22: AtomicUnitOf1stHyperpolarizability | C22: =proper(E22) -> Atomic Unit Of First Hyperpolarizability | D22: =UPPER(LEFT(F22,1))&MID(F22,2,LEN(F22)) -> Unité atomique de première hypolarisabilité | E22: atomic unit of first hyperpolarizability | F22: Unité atomique de première hypolarisabilité | G22: C^3 m^3 J^-2 | H22: =if(ISBLANK(G22),"",SUBSTITUTE(SUBSTITUTE(G22,"^","")," ","_")) -> C3_m3_J-2 | I22: =if(H22="","", countif(Units!A:A,H22)) -> 1 | J22: AtomicUnitOf1stHyperpolarizability | K22: =countif(Quantities!A:A,J22) -> 1 | L22: =J22=B22 -> TRUE | M22: AtomicUnitOf1stHyperpolarizablity | N22: =if(isblank(M22),"",hyperlink("https://qudt.org/vocab/constant/"&M22&".html","qudt")) -> qudt | O22: =not(isblank(M22)) -> TRUE | R22: =if(isblank(Q22),"",hyperlink("https://si-digital-framework.org/constants/"&Q22,"SI")) | S22: =sum(T22:Z22) -> 7 | T22: =countif('v2022'!E:E,A22) -> 1 | U22: =countif('v2018'!E:E,A22) -> 1 | V22: =countif('v2014'!E:E,A22) -> 1 | W22: =countif('v2010'!E:E,A22) -> 1 | X22: =countif('v2006'!E:E,A22) -> 1 | Y22: =countif('v2002'!E:E,A22) -> 1 | Z22: =countif('v1998'!E:E,A22) -> 1
A23: au2hypol | B23: AtomicUnitOf2ndHyperpolarizability | C23: =proper(E23) -> Atomic Unit Of Second Hyperpolarizability | D23: =UPPER(LEFT(F23,1))&MID(F23,2,LEN(F23)) -> Unité atomique de seconde hypolarisabilité | E23: atomic unit of second hyperpolarizability | F23: Unité atomique de seconde hypolarisabilité | G23: C^4 m^4 J^-3 | H23: =if(ISBLANK(G23),"",SUBSTITUTE(SUBSTITUTE(G23,"^","")," ","_")) -> C4_m4_J-3 | I23: =if(H23="","", countif(Units!A:A,H23)) -> 1 | J23: AtomicUnitOf2ndHyperpolarizability | K23: =countif(Quantities!A:A,J23) -> 1 | L23: =J23=B23 -> TRUE | M23: AtomicUnitOf2ndHyperpolarizablity | N23: =if(isblank(M23),"",hyperlink("https://qudt.org/vocab/constant/"&M23&".html","qudt")) -> qudt | O23: =not(isblank(M23)) -> TRUE | R23: =if(isblank(Q23),"",hyperlink("https://si-digital-framework.org/constants/"&Q23,"SI")) | S23: =sum(T23:Z23) -> 7 | T23: =countif('v2022'!E:E,A23) -> 1 | U23: =countif('v2018'!E:E,A23) -> 1 | V23: =countif('v2014'!E:E,A23) -> 1 | W23: =countif('v2010'!E:E,A23) -> 1 | X23: =countif('v2006'!E:E,A23) -> 1 | Y23: =countif('v2002'!E:E,A23) -> 1 | Z23: =countif('v1998'!E:E,A23) -> 1
A24: tthbar | B24: AtomicUnitOfAction | C24: =proper(E24) -> Atomic Unit Of Action | D24: =UPPER(LEFT(F24,1))&MID(F24,2,LEN(F24)) -> Unité atomique d'action | E24: atomic unit of action | F24: unité atomique d'action | G24: J s | H24: =if(ISBLANK(G24),"",SUBSTITUTE(SUBSTITUTE(G24,"^","")," ","_")) -> J_s | I24: =if(H24="","", countif(Units!A:A,H24)) -> 1 | J24: AtomicUnitOfAction | K24: =countif(Quantities!A:A,J24) -> 1 | L24: =J24=B24 -> TRUE | M24: AtomicUnitOfAction | N24: =if(isblank(M24),"",hyperlink("https://qudt.org/vocab/constant/"&M24&".html","qudt")) -> qudt | O24: =not(isblank(M24)) -> TRUE | R24: =if(isblank(Q24),"",hyperlink("https://si-digital-framework.org/constants/"&Q24,"SI")) | S24: =sum(T24:Z24) -> 7 | T24: =countif('v2022'!E:E,A24) -> 1 | U24: =countif('v2018'!E:E,A24) -> 1 | V24: =countif('v2014'!E:E,A24) -> 1 | W24: =countif('v2010'!E:E,A24) -> 1 | X24: =countif('v2006'!E:E,A24) -> 1 | Y24: =countif('v2002'!E:E,A24) -> 1 | Z24: =countif('v1998'!E:E,A24) -> 1
A25: Ae | B25: AtomicUnitOfCharge | C25: =proper(E25) -> Atomic Unit Of Charge | D25: =UPPER(LEFT(F25,1))&MID(F25,2,LEN(F25)) -> Unité atomique de charge | E25: atomic unit of charge | F25: unité atomique de charge | G25: C | H25: =if(ISBLANK(G25),"",SUBSTITUTE(SUBSTITUTE(G25,"^","")," ","_")) -> C | I25: =if(H25="","", countif(Units!A:A,H25)) -> 1 | J25: AtomicUnitOfCharge | K25: =countif(Quantities!A:A,J25) -> 1 | L25: =J25=B25 -> TRUE | M25: AtomicUnitOfCharge | N25: =if(isblank(M25),"",hyperlink("https://qudt.org/vocab/constant/"&M25&".html","qudt")) -> qudt | O25: =not(isblank(M25)) -> TRUE | P25: [e] | R25: =if(isblank(Q25),"",hyperlink("https://si-digital-framework.org/constants/"&Q25,"SI")) | S25: =sum(T25:Z25) -> 11 | T25: =countif('v2022'!E:E,A25) -> 2 | U25: =countif('v2018'!E:E,A25) -> 2 | V25: =countif('v2014'!E:E,A25) -> 2 | W25: =countif('v2010'!E:E,A25) -> 2 | X25: =countif('v2006'!E:E,A25) -> 1 | Y25: =countif('v2002'!E:E,A25) -> 1 | Z25: =countif('v1998'!E:E,A25) -> 1
A26: aucd | B26: AtomicUnitOfChargeDensity | C26: =proper(E26) -> Atomic Unit Of Charge Density | D26: =UPPER(LEFT(F26,1))&MID(F26,2,LEN(F26)) -> Unité atomique de densité de charge | E26: atomic unit of charge density | F26: unité atomique de densité de charge | G26: C m^-3 | H26: =if(ISBLANK(G26),"",SUBSTITUTE(SUBSTITUTE(G26,"^","")," ","_")) -> C_m-3 | I26: =if(H26="","", countif(Units!A:A,H26)) -> 1 | J26: AtomicUnitOfChargeDensity | K26: =countif(Quantities!A:A,J26) -> 1 | L26: =J26=B26 -> TRUE | M26: AtomicUnitOfChargeDensity | N26: =if(isblank(M26),"",hyperlink("https://qudt.org/vocab/constant/"&M26&".html","qudt")) -> qudt | O26: =not(isblank(M26)) -> TRUE | R26: =if(isblank(Q26),"",hyperlink("https://si-digital-framework.org/constants/"&Q26,"SI")) | S26: =sum(T26:Z26) -> 7 | T26: =countif('v2022'!E:E,A26) -> 1 | U26: =countif('v2018'!E:E,A26) -> 1 | V26: =countif('v2014'!E:E,A26) -> 1 | W26: =countif('v2010'!E:E,A26) -> 1 | X26: =countif('v2006'!E:E,A26) -> 1 | Y26: =countif('v2002'!E:E,A26) -> 1 | Z26: =countif('v1998'!E:E,A26) -> 1
A27: aucur | B27: AtomicUnitOfCurrent | C27: =proper(E27) -> Atomic Unit Of Current | D27: =UPPER(LEFT(F27,1))&MID(F27,2,LEN(F27)) -> Unité atomique de courant | E27: atomic unit of current | F27: unité atomique de courant | G27: A | H27: =if(ISBLANK(G27),"",SUBSTITUTE(SUBSTITUTE(G27,"^","")," ","_")) -> A | I27: =if(H27="","", countif(Units!A:A,H27)) -> 1 | J27: AtomicUnitOfCurrent | K27: =countif(Quantities!A:A,J27) -> 1 | L27: =J27=B27 -> TRUE | M27: AtomicUnitOfCurrent | N27: =if(isblank(M27),"",hyperlink("https://qudt.org/vocab/constant/"&M27&".html","qudt")) -> qudt | O27: =not(isblank(M27)) -> TRUE | R27: =if(isblank(Q27),"",hyperlink("https://si-digital-framework.org/constants/"&Q27,"SI")) | S27: =sum(T27:Z27) -> 7 | T27: =countif('v2022'!E:E,A27) -> 1 | U27: =countif('v2018'!E:E,A27) -> 1 | V27: =countif('v2014'!E:E,A27) -> 1 | W27: =countif('v2010'!E:E,A27) -> 1 | X27: =countif('v2006'!E:E,A27) -> 1 | Y27: =countif('v2002'!E:E,A27) -> 1 | Z27: =countif('v1998'!E:E,A27) -> 1
A28: auedm | B28: AtomicUnitOfElectricDipoleMoment | C28: =proper(E28) -> Atomic Unit Of Electric Dipole Moment | D28: =UPPER(LEFT(F28,1))&MID(F28,2,LEN(F28)) -> Unité atomique de moment dipolaire électrique | E28: atomic unit of electric dipole moment | F28: unité atomique de moment dipolaire électrique | G28: C m | H28: =if(ISBLANK(G28),"",SUBSTITUTE(SUBSTITUTE(G28,"^","")," ","_")) -> C_m | I28: =if(H28="","", countif(Units!A:A,H28)) -> 1 | J28: AtomicUnitOfElectricDipoleMoment | K28: =countif(Quantities!A:A,J28) -> 1 | L28: =J28=B28 -> TRUE | M28: AtomicUnitOfElectricDipoleMoment | N28: =if(isblank(M28),"",hyperlink("https://qudt.org/vocab/constant/"&M28&".html","qudt")) -> qudt | O28: =not(isblank(M28)) -> TRUE | R28: =if(isblank(Q28),"",hyperlink("https://si-digital-framework.org/constants/"&Q28,"SI")) | S28: =sum(T28:Z28) -> 7 | T28: =countif('v2022'!E:E,A28) -> 1 | U28: =countif('v2018'!E:E,A28) -> 1 | V28: =countif('v2014'!E:E,A28) -> 1 | W28: =countif('v2010'!E:E,A28) -> 1 | X28: =countif('v2006'!E:E,A28) -> 1 | Y28: =countif('v2002'!E:E,A28) -> 1 | Z28: =countif('v1998'!E:E,A28) -> 1
A29: auefld | B29: AtomicUnitOfElectricField | C29: =proper(E29) -> Atomic Unit Of Electric Field | D29: =UPPER(LEFT(F29,1))&MID(F29,2,LEN(F29)) -> Unité atomique de champ électrique | E29: atomic unit of electric field | F29: unité atomique de champ électrique | G29: V m^-1 | H29: =if(ISBLANK(G29),"",SUBSTITUTE(SUBSTITUTE(G29,"^","")," ","_")) -> V_m-1 | I29: =if(H29="","", countif(Units!A:A,H29)) -> 1 | J29: AtomicUnitOfElectricField | K29: =countif(Quantities!A:A,J29) -> 1 | L29: =J29=B29 -> TRUE | M29: AtomicUnitOfElectricField | N29: =if(isblank(M29),"",hyperlink("https://qudt.org/vocab/constant/"&M29&".html","qudt")) -> qudt | O29: =not(isblank(M29)) -> TRUE | R29: =if(isblank(Q29),"",hyperlink("https://si-digital-framework.org/constants/"&Q29,"SI")) | S29: =sum(T29:Z29) -> 7 | T29: =countif('v2022'!E:E,A29) -> 1 | U29: =countif('v2018'!E:E,A29) -> 1 | V29: =countif('v2014'!E:E,A29) -> 1 | W29: =countif('v2010'!E:E,A29) -> 1 | X29: =countif('v2006'!E:E,A29) -> 1 | Y29: =countif('v2002'!E:E,A29) -> 1 | Z29: =countif('v1998'!E:E,A29) -> 1
